Workbook

Sheet 8A
A1: N° | B1: NOMBRES Y APELLIDOS | C1: DOC. IDENTIDAD | D1: GRUPO | E1: DIRECTOR DE GRUPO | F1: JORNADA | G1: PERIODO | H1: AÑO | I1: IHS | J1: COG | K1: PROC | L1: ACT | M1: DEFIN | N1: DESEMP. | O1: IHS | P1: COG | Q1: PROC | R1: ACT | S1: DEFIN | T1: DESEMP. | U1: IHS | V1: COG | W1: PROC | X1: ACT | Y1: DEFIN | Z1: DESEMP. | AA1: IHS | AB1: COG | AC1: PROC | AD1: ACT | AE1: DEFIN | AF1: DESEMP. | AG1: IHS | AH1: COG | AI1: PROC | AJ1: ACT | AK1: DEFIN | AL1: DESEMP. | AM1: IHS | AN1: COG | AO1: PROC | AP1: ACT | AQ1: DEFIN | AR1: DESEMP. | AS1: IHS | AT1: COG | AU1: PROC | AV1: ACT | AW1: DEFIN | AX1: DESEMP. | AY1: IHS | AZ1: COG | BA1: PROC | BB1: ACT | BC1: DEFIN | BD1: DESEMP. | BE1: IHS | BF1: COG | BG1: PROC | BH1: ACT | BI1: DEFIN | BJ1: DESEMP. | BK1: IHS | BL1: COG | BM1: PROC | BN1: ACT | BO1: DEFIN | BP1: DESEMP. | BQ1: IHS | BR1: COG | BS1: PROC | BT1: ACT | BU1: DEFIN | BV1: DESEMP. | BW1: IHS | BX1: COG | BY1: PROC | BZ1: ACT | CA1: DEFIN | CB1: DESEMP. | CC1: IHS | CD1: COG | CE1: PROC | CF1: ACT | CG1: DEFIN | CH1: DESEMP. | CI1: IHS | CJ1: COG | CK1: PROC | CL1: ACT | CM1: DEFIN | CN1: DESEMP. | CO1: IHS | CP1: COG | CQ1: PROC | CR1: ACT | CS1: DEFIN | CT1: DESEMP. | CU1: IHS | CV1: COG | CW1: PROC | CX1: ACT | CY1: DEFIN | CZ1: DESEMP. | DA1: IHS | DB1: COG | DC1: PROC | DD1: ACT | DE1: DEFIN | DF1: DESEMP. | DG1: IHS | DH1: DEFIN | DI1: DESEMP. | DJ1: PROMEDIO | DK1: L. MAT C | DL1: L MAT P | DM1: L MAT A | DN1: L. ESTAD C | DO1: L. ESTAD P | DP1: L. ESTAD A | DQ1: L LEN C | DR1: L LEN P | DS1: L LEN A | DT1: L LC C | DU1: L LC P | DV1: L LC A | DW1: L. FINGL C | DX1: L. FINGL P | DY1: L. FINGL A | DZ1: L. SPEAK C | EA1: L. SPEAK P | EB1: L. PSEAK A | EC1: L BIO C | ED1: L BIO P | EE1: L BIO A | EF1: L MAM C | EG1: L MAM P | EH1: L MAM A | EI1: L SOC C | EJ1: L SOC P | EK1: L SOC A | EL1: L HIS C | EM1: L HIS P | EN1: L HIS A | EO1: L GEOG C | EP1: L GEOG P | EQ1: L GEOG A | ER1: L CPAZ C | ES1: L CPAZ P | ET1: L CPAZ A | EU1: L. ET C | EV1: L ET P | EW1: L ET A | EX1: L REL C | EY1: L REL P | EZ1: L REL A | FA1: L ART C | FB1: L ART P | FC1: L ART A | FD1: L EF C | FE1: L EF P | FF1: L EF A | FG1: L INF C | FH1: L INF P | FI1: L INF A | FJ1: L CONV
A2: 1 | B2: ACOSTA ROCHA DANIEL ANTONIO | C2: 1044644667 | D2: 8°A | E2: Yenis María Duncan Ramirez | F2: Mañana | G2: PRIMERO | H2: 2026 | I2: 4 | J2: 2.8 | K2: 3 | L2: 3.2 | M2: =((J2*0.3)+(K2*0.4)+(L2*0.3)) -> 3 | N2: =IF(M2<3,"BAJO",IF(M2<4,"BASICO",IF(M2<4.5,"ALTO",IF(M2<=5,"SUPERIOR")))) -> BASICO | O2: 1 | P2: 2.8 | Q2: 2.8 | R2: 2.8 | S2: =((P2*0.3)+(Q2*0.4)+(R2*0.3)) -> 2.8 | T2: =IF(S2<3,"BAJO",IF(S2<4,"BASICO",IF(S2<4.5,"ALTO",IF(S2<=5,"SUPERIOR")))) -> BAJO | U2: 4 | V2: 4 | W2: 4 | X2: 4 | Y2: =((V2*0.3)+(W2*0.4)+(X2*0.3)) -> 4 | Z2: =IF(Y2<3,"BAJO",IF(Y2<4,"BASICO",IF(Y2<4.5,"ALTO",IF(Y2<=5,"SUPERIOR")))) -> ALTO | AA2: 1 | AB2: 3 | AC2: 3 | AD2: 3 | AE2: =((AB2*0.3)+(AC2*0.4)+(AD2*0.3)) -> 3 | AF2: =IF(AE2<3,"BAJO",IF(AE2<4,"BASICO",IF(AE2<4.5,"ALTO",IF(AE2<=5,"SUPERIOR")))) -> BASICO | AG2: 2 | AH2: 3.5 | AI2: 3 | AJ2: 3 | AK2: =((AH2*0.3)+(AI2*0.4)+(AJ2*0.3)) -> 3.15 | AL2: =IF(AK2<3,"BAJO",IF(AK2<4,"BASICO",IF(AK2<4.5,"ALTO",IF(AK2<=5,"SUPERIOR")))) -> BASICO | AM2: 1 | AN2: 3.5 | AO2: 3 | AP2: 3 | AQ2: =((AN2*0.3)+(AO2*0.4)+(AP2*0.3)) -> 3.15 | AR2: =IF(AQ2<3,"BAJO",IF(AQ2<4,"BASICO",IF(AQ2<4.5,"ALTO",IF(AQ2<=5,"SUPERIOR")))) -> BASICO | AS2: 4 | AT2: 3 | AU2: 3 | AV2: 3 | AW2: =((AT2*0.3)+(AU2*0.4)+(AV2*0.3)) -> 3 | AX2: =IF(AW2<3,"BAJO",IF(AW2<4,"BASICO",IF(AW2<4.5,"ALTO",IF(AW47<=5,"SUPERIOR")))) -> BASICO | AY2: 1 | AZ2: 3.8 | BA2: 4 | BB2: 4 | BC2: =((AZ2*0.3)+(BA2*0.4)+(BB2*0.3)) -> 3.94 | BD2: =IF(BC2<3,"BAJO",IF(BC2<4,"BASICO",IF(BC2<4.5,"ALTO",IF(BC2<=5,"SUPERIOR")))) -> BASICO | BE2: 2 | BF2: 3.4 | BG2: 3.2 | BH2: 3.2 | BI2: =((BF2*0.3)+(BG2*0.4)+(BH2*0.3)) -> 3.26 | BJ2: =IF(BI2<3,"BAJO",IF(BI2<4,"BASICO",IF(BI2<4.5,"ALTO",IF(BI2<=5,"SUPERIOR")))) -> BASICO | BK2: 1 | BL2: 3.4 | BM2: 3.2 | BN2: 3.4 | BO2: =((BL2*0.3)+(BM2*0.4)+(BN2*0.3)) -> 3.32 | BP2: =IF(BO2<3,"BAJO",IF(BO2<4,"BASICO",IF(BO2<4.5,"ALTO",IF(BO2<=5,"SUPERIOR")))) -> BASICO | BQ2: 1 | BR2: 3.4 | BS2: 3.4 | BT2: 3.2 | BU2: =((BR2*0.3)+(BS2*0.4)+(BT2*0.3)) -> 3.34 | BV2: =IF(BU2<3,"BAJO",IF(BU2<4,"BASICO",IF(BU2<4.5,"ALTO",IF(BU2<=5,"SUPERIOR")))) -> BASICO | BW2: 1 | BX2: 2.5 | BY2: 2.5 | BZ2: 2.5 | CA2: =((BX2*0.3)+(BY2*0.4)+(BZ2*0.3)) -> 2.5 | CB2: =IF(CA2<3,"BAJO",IF(CA2<4,"BASICO",IF(CA2<4.5,"ALTO",IF(CA2<=5,"SUPERIOR")))) -> BAJO | CC2: 1 | CD2: 3.7 | CE2: 3.5 | CF2: 3.5 | CG2: =((CD2*0.3)+(CE2*0.4)+(CF2*0.3)) -> 3.56 | CH2: =IF(CG2<3,"BAJO",IF(CG2<4,"BASICO",IF(CG2<4.5,"ALTO",IF(CG2<=5,"SUPERIOR")))) -> BASICO | CI2: 1 | CJ2: 4.4 | CK2: 4.4 | CL2: 4.4 | CM2: =((CJ2*0.3)+(CK2*0.4)+(CL2*0.3)) -> 4.4 | CN2: =IF(CM2<3,"BAJO",IF(CM2<4,"BASICO",IF(CM2<4.5,"ALTO",IF(CM2<=5,"SUPERIOR")))) -> ALTO | CO2: 1 | CP2: 5 | CQ2: 5 | CR2: 5 | CS2: =((CP2*0.3)+(CQ2*0.4)+(CR2*0.3)) -> 5 | CT2: =IF(CS2<3,"BAJO",IF(CS2<4,"BASICO",IF(CS2<4.5,"ALTO",IF(CS2<=5,"SUPERIOR")))) -> SUPERIOR | CU2: 2 | CV2: 2 | CW2: 2 | CX2: 2 | CY2: =((CV2*0.3)+(CW2*0.4)+(CX2*0.3)) -> 2 | CZ2: =IF(CY2<3,"BAJO",IF(CY2<4,"BASICO",IF(CY2<4.5,"ALTO",IF(CY2<=5,"SUPERIOR")))) -> BAJO | DA2: 2 | DB2: 2 | DC2: 2 | DD2: 3.5 | DE2: =((DB2*0.3)+(DC2*0.4)+(DD2*0.3)) -> 2.45 | DF2: =IF(DE2<2.95,"BAJO",IF(DE2<3.95,"BASICO",IF(DE2<4.45,"ALTO",IF(DE2<=5,"SUPERIOR")))) -> BAJO | DG2: 0 | DI2: =IF(DH2<3,"BAJO",IF(DH2<4,"BASICO",IF(DH2<4.5,"ALTO",IF(DH2<=5,"SUPERIOR")))) -> BAJO | DJ2: =AVERAGE(M2,Y2,AE2,AK2,AW2,BC2,BI2,BO2,CA2,DE2,DH2,CY2,CS2,CM2,CG2,AQ2,S2) -> 3.283125 | DK2: =DESEMPEÑOS!B2 -> Comprende el concepto de números reales, su relación de orden y las propiedades de sus operaciones, así como las relaciones de semejanza y congruencia de distintas figuras geométricas. | DL2: =DESEMPEÑOS!C2 -> Aplica correctamente las propiedades de las operaciones de números reales y expresiones algebraicas en la resolución de problemas. | DM2: =DESEMPEÑOS!D2 -> Valora el uso del pensamiento lógico a la hora de plantear y resolver problemas de las matemáticas y de la vida cotidiana. | DN2: =DESEMPEÑOS!B3 -> Reconoce y clasifica variables aleatorias, comprendiendo sus tipos y características; además, interpreta la información presentada en tablas de frecuencias y diagramas estadísticos, explicando su significado en contextos diversos. | DO2: =DESEMPEÑOS!C3 -> Organiza y analiza datos mediante la construcción de tablas de frecuencias y diagramas estadísticos, identificando variables aleatorias y utilizando estas representaciones para resolver situaciones problema. | DP2: =DESEMPEÑOS!D3 -> Muestra disposición y responsabilidad en el manejo y análisis de datos, participando activamente en actividades individuales y colaborativas, y comunicando información estadística con claridad y sentido crítico. | DQ2: =DESEMPEÑOS!B4 -> Analiza las características de la literatura prehispánica y la literatura del descubrimiento y la conquista en Colombia identificando sus elementos fundamentales y su impacto en la cultura y el lenguaje actual. | DR2: =DESEMPEÑOS!C4 -> Realiza comprensión lectora cuando analiza un texto desde el discurso de la Enunciación e identifica la función de cada uno de sus componentes. Responde preguntas en los tres niveles de lectura a una leyenda del Caribe. | DS2: =DESEMPEÑOS!D4 -> Muestra disposición para participar activamente en las clases, promoviendo el respeto por las ideas ajenas y reconociendo la importancia de la precisión como una herramienta clave para una comunicación | DT2: =DESEMPEÑOS!B5 -> Comprende el contenido del cuento A la deriva, identificando su tema central, la secuencia de los hechos, los personajes y las ideas explícitas e implícitas del texto. | DU2: =DESEMPEÑOS!C5 -> Analiza críticamente el cuento A la deriva mediante la identificación de información literal, inferencial y crítica, sustentando sus respuestas de forma oral y escrita. | DV2: =DESEMPEÑOS!D5 -> Valora la lectura literaria como una oportunidad para reflexionar sobre la vida, la naturaleza y la condición humana, participando con interés, respeto y sentido crítico en las actividades propuestas. | DW2: =DESEMPEÑOS!B6 -> Comprende y reconoce vocabulario y estructuras basicas del ingles para interpretar textos cortos y conversaciones sobre temas cotidianos de la vida diaria. | DX2: =DESEMPEÑOS!C6 -> Produce de forma oral y escrita frases y parrafos cortos en Ingles, utilizando correctamente las estructuras conocidas para describir rutinas, narrar experiencias y participar en conversaciones. | DY2: =DESEMPEÑOS!D6 -> Muestra disposicion positiva hacia el aprendizaje del Ingles participando activamente en clase. | DZ2: =DESEMPEÑOS!B7 -> Identifica vocabulario en Ingles de situaciones cotidianas. | EA2: =DESEMPEÑOS!C7 -> Participa en actividades utilizando vocabulario aprendido para expresar gustos,emociones y necesidades. | EB2: =DESEMPEÑOS!D7 -> Respeta la opinion de los demas, muestra disposicion para participar en actividades orales. | EC2: =DESEMPEÑOS!B8 -> Identifica la conformación y funcionamiento del sistema inmunolófico y diferencia las característics de los estados de la materia. | ED2: =DESEMPEÑOS!C8 -> Reconoce experimentalmente las características de materiales en los diferentes estados de la materia. | EE2: =DESEMPEÑOS!D8 -> Valora la importancia de tener habitos saludables, para lograr el mantenimiento saludable del sistema inmune. | EF2: =DESEMPEÑOS!B9 -> Describe correctamente la secuencia de eventos biologicos de la fecundacion,incluyendo las recciones acrosomicas,la funcion de gametos y la formacion de gametos. | EG2: =DESEMPEÑOS!C9 -> Mide la capacidad del labolatrio para lograr la fecundacion exitosa de los ovulos con el espermatozoide. | EH2: =DESEMPEÑOS!D9 -> Valora la importancia del cuidado del cuerpo y de la salud reproductiva como la base para una fecundacion saludable. | EI2: =DESEMPEÑOS!B10 -> Explico las principales caracteristicas de algunas revoluciones de los siglos XVIII y XIX (Revolucion francesa, Industrial...) | EJ2: =DESEMPEÑOS!C10 -> Analiza las causas y consecuencias de procesos historicos como la Revolucion Industrial y Francesa. | EK2: =DESEMPEÑOS!D10 -> Muestra interes y curiosidad por comprender los procesos historicos y su impacto en la sociedad. | EL2: =DESEMPEÑOS!B11 -> Identifica los procesos historicos de algunas revoluciones de los siglos XVIII y XIX | EM2: =DESEMPEÑOS!C11 -> 0 | EN2: =DESEMPEÑOS!D11 -> 0 | EO2: =DESEMPEÑOS!B12 -> Comprende la distribucion espacial de la poblacion antes y despues de las revoluciones | EP2: =DESEMPEÑOS!C12 -> Ubica en mapas las regiones donde se desarrollaron las principales revoluciones y explica sus caracteristicas geograficas | EQ2: =DESEMPEÑOS!D12 -> Muestra interes por comprender la relacion entre sociedad, economia y territorio | ER2: =DESEMPEÑOS!B13 -> Comprende el concepto de cultura de paz y su importancia en la sociedad | ES2: =DESEMPEÑOS!C13 -> Practica normas de convivencia en diferentes espacios( aula, hogar, comunidad) | ET2: =DESEMPEÑOS!D13 -> Muestra actitud de respeto hacia la diversidad cuktural, social y de pensamiento | EU2: =DESEMPEÑOS!B14 -> 0 | EV2: =DESEMPEÑOS!C14 -> 0 | EW2: =DESEMPEÑOS!D14 -> 0 | EX2: =DESEMPEÑOS!B15 -> 0 | EY2: =DESEMPEÑOS!C15 -> 0 | EZ2: =DESEMPEÑOS!D15 -> 0 | FA2: =DESEMPEÑOS!B16 -> 0 | FB2: =DESEMPEÑOS!C16 -> 0 | FC2: =DESEMPEÑOS!D16 -> 0 | FD2: =DESEMPEÑOS!B17 -> Identifica las expresiones motrices relacionadas con el juego del voleibol, como una oportunidad para mejorar la salud, la estética y las relaciones con los demás. | FE2: =DESEMPEÑOS!C17 -> Pone en práctica los fundamentos básicos del voleibol. | FF2: =DESEMPEÑOS!D17 -> Muestra responsabilidad y buena actitud al realizar el juego de voleibol. | FG2: =DESEMPEÑOS!B18 -> Comprende el concepto de variable como espacio de almacenamiento de datos y reconoce el uso de estructuras condicionales (si, si-no) para la toma de decisiones en un programa. | FH2: =DESEMPEÑOS!C18 -> Diseña y desarrolla programas que utilizan variables y estructuras condicionales para resolver problemas, evaluando condiciones y generando respuestas según diferentes situaciones. | FI2: =DESEMPEÑOS!D18 -> Muestra pensamiento lógico, perseverancia y actitud crítica al analizar errores y proponer soluciones en la construcción de programas con variables y condicionales. | FJ2: =DESEMPEÑOS!B19 -> Identifica y reconoce sus pricipales deberes y derechos dentro y fuera de la Institución educativa.
A3: 2 | B3: ALEMAN MORALES JUAN SEBASTIAN | C3: 1143238454 | D3: 8°A | E3: Yenis María Duncan Ramirez | F3: Mañana | G3: PRIMERO | H3: 2026 | I3: 4 | M3: =((J3*0.3)+(K3*0.4)+(L3*0.3)) -> 0 | N3: =IF(M3<3,"BAJO",IF(M3<4,"BASICO",IF(M3<4.5,"ALTO",IF(M3<=5,"SUPERIOR")))) -> BAJO | O3: 1 | S3: =((P3*0.3)+(Q3*0.4)+(R3*0.3)) -> 0 | T3: =IF(S3<3,"BAJO",IF(S3<4,"BASICO",IF(S3<4.5,"ALTO",IF(S3<=5,"SUPERIOR")))) -> BAJO | U3: 4 | Y3: =((V3*0.3)+(W3*0.4)+(X3*0.3)) -> 0 | Z3: =IF(Y3<3,"BAJO",IF(Y3<4,"BASICO",IF(Y3<4.5,"ALTO",IF(Y3<=5,"SUPERIOR")))) -> BAJO | AA3: 1 | AE3: =((AB3*0.3)+(AC3*0.4)+(AD3*0.3)) -> 0 | AF3: =IF(AE3<3,"BAJO",IF(AE3<4,"BASICO",IF(AE3<4.5,"ALTO",IF(AE3<=5,"SUPERIOR")))) -> BAJO | AG3: 2 | AK3: =((AH3*0.3)+(AI3*0.4)+(AJ3*0.3)) -> 0 | AL3: =IF(AK3<3,"BAJO",IF(AK3<4,"BASICO",IF(AK3<4.5,"ALTO",IF(AK3<=5,"SUPERIOR")))) -> BAJO | AM3: 1 | AQ3: =((AN3*0.3)+(AO3*0.4)+(AP3*0.3)) -> 0 | AR3: =IF(AQ3<3,"BAJO",IF(AQ3<4,"BASICO",IF(AQ3<4.5,"ALTO",IF(AQ3<=5,"SUPERIOR")))) -> BAJO | AS3: 4 | AW3: =((AT3*0.3)+(AU3*0.4)+(AV3*0.3)) -> 0 | AX3: =IF(AW3<3,"BAJO",IF(AW3<4,"BASICO",IF(AW3<4.5,"ALTO",IF(AW48<=5,"SUPERIOR")))) -> BAJO | AY3: 1 | BC3: =((AZ3*0.3)+(BA3*0.4)+(BB3*0.3)) -> 0 | BD3: =IF(BC3<3,"BAJO",IF(BC3<4,"BASICO",IF(BC3<4.5,"ALTO",IF(BC3<=5,"SUPERIOR")))) -> BAJO | BE3: 2 | BI3: =((BF3*0.3)+(BG3*0.4)+(BH3*0.3)) -> 0 | BJ3: =IF(BI3<3,"BAJO",IF(BI3<4,"BASICO",IF(BI3<4.5,"ALTO",IF(BI3<=5,"SUPERIOR")))) -> BAJO | BK3: 1 | BO3: =((BL3*0.3)+(BM3*0.4)+(BN3*0.3)) -> 0 | BP3: =IF(BO3<3,"BAJO",IF(BO3<4,"BASICO",IF(BO3<4.5,"ALTO",IF(BO3<=5,"SUPERIOR")))) -> BAJO | BQ3: 1 | BU3: =((BR3*0.3)+(BS3*0.4)+(BT3*0.3)) -> 0 | BV3: =IF(BU3<3,"BAJO",IF(BU3<4,"BASICO",IF(BU3<4.5,"ALTO",IF(BU3<=5,"SUPERIOR")))) -> BAJO | BW3: 1 | CA3: =((BX3*0.3)+(BY3*0.4)+(BZ3*0.3)) -> 0 | CB3: =IF(CA3<3,"BAJO",IF(CA3<4,"BASICO",IF(CA3<4.5,"ALTO",IF(CA3<=5,"SUPERIOR")))) -> BAJO | CC3: 1 | CG3: =((CD3*0.3)+(CE3*0.4)+(CF3*0.3)) -> 0 | CH3: =IF(CG3<3,"BAJO",IF(CG3<4,"BASICO",IF(CG3<4.5,"ALTO",IF(CG3<=5,"SUPERIOR")))) -> BAJO | CI3: 1 | CM3: =((CJ3*0.3)+(CK3*0.4)+(CL3*0.3)) -> 0 | CN3: =IF(CM3<3,"BAJO",IF(CM3<4,"BASICO",IF(CM3<4.5,"ALTO",IF(CM3<=5,"SUPERIOR")))) -> BAJO | CO3: 1 | CS3: =((CP3*0.3)+(CQ3*0.4)+(CR3*0.3)) -> 0 | CT3: =IF(CS3<3,"BAJO",IF(CS3<4,"BASICO",IF(CS3<4.5,"ALTO",IF(CS3<=5,"SUPERIOR")))) -> BAJO | CU3: 2 | CY3: =((CV3*0.3)+(CW3*0.4)+(CX3*0.3)) -> 0 | CZ3: =IF(CY3<3,"BAJO",IF(CY3<4,"BASICO",IF(CY3<4.5,"ALTO",IF(CY3<=5,"SUPERIOR")))) -> BAJO | DA3: 2 | DE3: =((DB3*0.3)+(DC3*0.4)+(DD3*0.3)) -> 0 | DF3: =IF(DE3<2.95,"BAJO",IF(DE3<3.95,"BASICO",IF(DE3<4.45,"ALTO",IF(DE3<=5,"SUPERIOR")))) -> BAJO | DG3: 0 | DI3: =IF(DH3<3,"BAJO",IF(DH3<4,"BASICO",IF(DH3<4.5,"ALTO",IF(DH3<=5,"SUPERIOR")))) -> BAJO | DJ3: =AVERAGE(M3,Y3,AE3,AK3,AW3,BC3,BI3,BO3,CA3,DE3,DH3,CY3,CS3,CM3,CG3,AQ3,S3) -> 0 | DK3: =$DK$2 -> Comprende el concepto de números reales, su relación de orden y las propiedades de sus operaciones, así como las relaciones de semejanza y congruencia de distintas figuras geométricas. | DL3: =DL2 -> Aplica correctamente las propiedades de las operaciones de números reales y expresiones algebraicas en la resolución de problemas. | DM3: =DM2 -> Valora el uso del pensamiento lógico a la hora de plantear y resolver problemas de las matemáticas y de la vida cotidiana. | DN3: =DN2 -> Reconoce y clasifica variables aleatorias, comprendiendo sus tipos y características; además, interpreta la información presentada en tablas de frecuencias y diagramas estadísticos, explicando su significado en contextos diversos. | DO3: =DO2 -> Organiza y analiza datos mediante la construcción de tablas de frecuencias y diagramas estadísticos, identificando variables aleatorias y utilizando estas representaciones para resolver situaciones problema. | DP3: =DP2 -> Muestra disposición y responsabilidad en el manejo y análisis de datos, participando activamente en actividades individuales y colaborativas, y comunicando información estadística con claridad y sentido crítico. | DQ3: =DQ2 -> Analiza las características de la literatura prehispánica y la literatura del descubrimiento y la conquista en Colombia identificando sus elementos fundamentales y su impacto en la cultura y el lenguaje actual. | DR3: =DR2 -> Realiza comprensión lectora cuando analiza un texto desde el discurso de la Enunciación e identifica la función de cada uno de sus componentes. Responde preguntas en los tres niveles de lectura a una leyenda del Caribe. | DS3: =DS2 -> Muestra disposición para participar activamente en las clases, promoviendo el respeto por las ideas ajenas y reconociendo la importancia de la precisión como una herramienta clave para una comunicación | ... FJ3: =FJ2 -> Identifica y reconoce sus pricipales deberes y derechos dentro y fuera de la Institución educativa.
A4: 3 | B4: ALVAREZ SALAS LUISA ISABELLA | C4: 1052090077 | D4: 8°A | E4: Yenis María Duncan Ramirez | F4: Mañana | G4: PRIMERO | H4: 2026 | I4: 4 | J4: 2.4 | K4: 2.5 | L4: 2.6 | M4: =((J4*0.3)+(K4*0.4)+(L4*0.3)) -> 2.5 | N4: =IF(M4<3,"BAJO",IF(M4<4,"BASICO",IF(M4<4.5,"ALTO",IF(M4<=5,"SUPERIOR")))) -> BAJO | O4: 1 | P4: 3.6 | Q4: 3.6 | R4: 3.6 | S4: =((P4*0.3)+(Q4*0.4)+(R4*0.3)) -> 3.6 | T4: =IF(S4<3,"BAJO",IF(S4<4,"BASICO",IF(S4<4.5,"ALTO",IF(S4<=5,"SUPERIOR")))) -> BASICO | U4: 4 | V4: 3.7 | W4: 3.5 | X4: 3.8 | Y4: =((V4*0.3)+(W4*0.4)+(X4*0.3)) -> 3.65 | Z4: =IF(Y4<3,"BAJO",IF(Y4<4,"BASICO",IF(Y4<4.5,"ALTO",IF(Y4<=5,"SUPERIOR")))) -> BASICO | AA4: 1 | AB4: 4 | AC4: 4 | AD4: 4 | AE4: =((AB4*0.3)+(AC4*0.4)+(AD4*0.3)) -> 4 | AF4: =IF(AE4<3,"BAJO",IF(AE4<4,"BASICO",IF(AE4<4.5,"ALTO",IF(AE4<=5,"SUPERIOR")))) -> ALTO | AG4: 2 | AH4: 2.5 | AI4: 3 | AJ4: 3 | AK4: =((AH4*0.3)+(AI4*0.4)+(AJ4*0.3)) -> 2.85 | AL4: =IF(AK4<3,"BAJO",IF(AK4<4,"BASICO",IF(AK4<4.5,"ALTO",IF(AK4<=5,"SUPERIOR")))) -> BAJO | AM4: 1 | AN4: 2.5 | AO4: 3 | AP4: 3 | AQ4: =((AN4*0.3)+(AO4*0.4)+(AP4*0.3)) -> 2.85 | AR4: =IF(AQ4<3,"BAJO",IF(AQ4<4,"BASICO",IF(AQ4<4.5,"ALTO",IF(AQ4<=5,"SUPERIOR")))) -> BAJO | AS4: 4 | AT4: 2.5 | AU4: 2.5 | AV4: 2.5 | AW4: =((AT4*0.3)+(AU4*0.4)+(AV4*0.3)) -> 2.5 | AX4: =IF(AW4<3,"BAJO",IF(AW4<4,"BASICO",IF(AW4<4.5,"ALTO",IF(AW49<=5,"SUPERIOR")))) -> BAJO | AY4: 1 | AZ4: 4 | BA4: 3.6 | BB4: 3.5 | BC4: =((AZ4*0.3)+(BA4*0.4)+(BB4*0.3)) -> 3.69 | BD4: =IF(BC4<3,"BAJO",IF(BC4<4,"BASICO",IF(BC4<4.5,"ALTO",IF(BC4<=5,"SUPERIOR")))) -> BASICO | BE4: 2 | BF4: 3.4 | BG4: 3.2 | BH4: 3 | BI4: =((BF4*0.3)+(BG4*0.4)+(BH4*0.3)) -> 3.2 | BJ4: =IF(BI4<3,"BAJO",IF(BI4<4,"BASICO",IF(BI4<4.5,"ALTO",IF(BI4<=5,"SUPERIOR")))) -> BASICO | BK4: 1 | BL4: 3.4 | BM4: 3.2 | BN4: 3.2 | BO4: =((BL4*0.3)+(BM4*0.4)+(BN4*0.3)) -> 3.26 | BP4: =IF(BO4<3,"BAJO",IF(BO4<4,"BASICO",IF(BO4<4.5,"ALTO",IF(BO4<=5,"SUPERIOR")))) -> BASICO | BQ4: 1 | BR4: 3.2 | BS4: 3.2 | BT4: 3.2 | BU4: =((BR4*0.3)+(BS4*0.4)+(BT4*0.3)) -> 3.2 | BV4: =IF(BU4<3,"BAJO",IF(BU4<4,"BASICO",IF(BU4<4.5,"ALTO",IF(BU4<=5,"SUPERIOR")))) -> BASICO | BW4: 1 | BX4: 3 | BY4: 3 | BZ4: 3 | CA4: =((BX4*0.3)+(BY4*0.4)+(BZ4*0.3)) -> 3 | CB4: =IF(CA4<3,"BAJO",IF(CA4<4,"BASICO",IF(CA4<4.5,"ALTO",IF(CA4<=5,"SUPERIOR")))) -> BASICO | CC4: 1 | CD4: 3.5 | CE4: 3.7 | CF4: 3.7 | CG4: =((CD4*0.3)+(CE4*0.4)+(CF4*0.3)) -> 3.64 | CH4: =IF(CG4<3,"BAJO",IF(CG4<4,"BASICO",IF(CG4<4.5,"ALTO",IF(CG4<=5,"SUPERIOR")))) -> BASICO | CI4: 1 | CJ4: 4.4 | CK4: 4.2 | CL4: 4.2 | CM4: =((CJ4*0.3)+(CK4*0.4)+(CL4*0.3)) -> 4.26 | CN4: =IF(CM4<3,"BAJO",IF(CM4<4,"BASICO",IF(CM4<4.5,"ALTO",IF(CM4<=5,"SUPERIOR")))) -> ALTO | CO4: 1 | CP4: 3.5 | CQ4: 3.5 | CR4: 3.5 | CS4: =((CP4*0.3)+(CQ4*0.4)+(CR4*0.3)) -> 3.5 | CT4: =IF(CS4<3,"BAJO",IF(CS4<4,"BASICO",IF(CS4<4.5,"ALTO",IF(CS4<=5,"SUPERIOR")))) -> BASICO | CU4: 2 | CV4: 3.5 | CW4: 3.5 | CX4: 3.5 | CY4: =((CV4*0.3)+(CW4*0.4)+(CX4*0.3)) -> 3.5 | CZ4: =IF(CY4<3,"BAJO",IF(CY4<4,"BASICO",IF(CY4<4.5,"ALTO",IF(CY4<=5,"SUPERIOR")))) -> BASICO | DA4: 2 | DB4: 3.5 | DC4: 3.5 | DD4: 3 | DE4: =((DB4*0.3)+(DC4*0.4)+(DD4*0.3)) -> 3.35 | DF4: =IF(DE4<2.95,"BAJO",IF(DE4<3.95,"BASICO",IF(DE4<4.45,"ALTO",IF(DE4<=5,"SUPERIOR")))) -> BASICO | DG4: 0 | DI4: =IF(DH4<3,"BAJO",IF(DH4<4,"BASICO",IF(DH4<4.5,"ALTO",IF(DH4<=5,"SUPERIOR")))) -> BAJO | DJ4: =AVERAGE(M4,Y4,AE4,AK4,AW4,BC4,BI4,BO4,CA4,DE4,DH4,CY4,CS4,CM4,CG4,AQ4,S4) -> 3.334375 | DK4: =$DK$2 -> Comprende el concepto de números reales, su relación de orden y las propiedades de sus operaciones, así como las relaciones de semejanza y congruencia de distintas figuras geométricas. | DL4: =DL3 -> Aplica correctamente las propiedades de las operaciones de números reales y expresiones algebraicas en la resolución de problemas. | DM4: =DM3 -> Valora el uso del pensamiento lógico a la hora de plantear y resolver problemas de las matemáticas y de la vida cotidiana. | DN4: =DN3 -> Reconoce y clasifica variables aleatorias, comprendiendo sus tipos y características; además, interpreta la información presentada en tablas de frecuencias y diagramas estadísticos, explicando su significado en contextos diversos. | DO4: =DO3 -> Organiza y analiza datos mediante la construcción de tablas de frecuencias y diagramas estadísticos, identificando variables aleatorias y utilizando estas representaciones para resolver situaciones problema. | DP4: =DP3 -> Muestra disposición y responsabilidad en el manejo y análisis de datos, participando activamente en actividades individuales y colaborativas, y comunicando información estadística con claridad y sentido crítico. | DQ4: =DQ3 -> Analiza las características de la literatura prehispánica y la literatura del descubrimiento y la conquista en Colombia identificando sus elementos fundamentales y su impacto en la cultura y el lenguaje actual. | DR4: =DR3 -> Realiza comprensión lectora cuando analiza un texto desde el discurso de la Enunciación e identifica la función de cada uno de sus componentes. Responde preguntas en los tres niveles de lectura a una leyenda del Caribe. | DS4: =DS3 -> Muestra disposición para participar activamente en las clases, promoviendo el respeto por las ideas ajenas y reconociendo la importancia de la precisión como una herramienta clave para una comunicación | ... FJ4: =FJ3 -> Identifica y reconoce sus pricipales deberes y derechos dentro y fuera de la Institución educativa.
A5: 4 | B5: CABALLERO MACHADO BREINER JAFETH | C5: 1143144977 | D5: 8°A | E5: Yenis María Duncan Ramirez | F5: Mañana | G5: PRIMERO | H5: 2026 | I5: 4 | J5: 3 | K5: 3.2 | L5: 3.4 | M5: =((J5*0.3)+(K5*0.4)+(L5*0.3)) -> 3.2 | N5: =IF(M5<3,"BAJO",IF(M5<4,"BASICO",IF(M5<4.5,"ALTO",IF(M5<=5,"SUPERIOR")))) -> BASICO | O5: 1 | P5: 4.4 | Q5: 4.4 | R5: 4.4 | S5: =((P5*0.3)+(Q5*0.4)+(R5*0.3)) -> 4.4 | T5: =IF(S5<3,"BAJO",IF(S5<4,"BASICO",IF(S5<4.5,"ALTO",IF(S5<=5,"SUPERIOR")))) -> ALTO | U5: 4 | V5: 4 | W5: 4 | X5: 3 | Y5: =((V5*0.3)+(W5*0.4)+(X5*0.3)) -> 3.7 | Z5: =IF(Y5<3,"BAJO",IF(Y5<4,"BASICO",IF(Y5<4.5,"ALTO",IF(Y5<=5,"SUPERIOR")))) -> BASICO | AA5: 1 | AB5: 3.4 | AC5: 3.4 | AD5: 3.4 | AE5: =((AB5*0.3)+(AC5*0.4)+(AD5*0.3)) -> 3.4 | AF5: =IF(AE5<3,"BAJO",IF(AE5<4,"BASICO",IF(AE5<4.5,"ALTO",IF(AE5<=5,"SUPERIOR")))) -> BASICO | AG5: 2 | AH5: 3.5 | AI5: 3.5 | AJ5: 3.5 | AK5: =((AH5*0.3)+(AI5*0.4)+(AJ5*0.3)) -> 3.5 | AL5: =IF(AK5<3,"BAJO",IF(AK5<4,"BASICO",IF(AK5<4.5,"ALTO",IF(AK5<=5,"SUPERIOR")))) -> BASICO | AM5: 1 | AN5: 3.5 | AO5: 3.5 | AP5: 3.5 | AQ5: =((AN5*0.3)+(AO5*0.4)+(AP5*0.3)) -> 3.5 | AR5: =IF(AQ5<3,"BAJO",IF(AQ5<4,"BASICO",IF(AQ5<4.5,"ALTO",IF(AQ5<=5,"SUPERIOR")))) -> BASICO | AS5: 4 | AT5: 2.5 | AU5: 2.5 | AV5: 2.5 | AW5: =((AT5*0.3)+(AU5*0.4)+(AV5*0.3)) -> 2.5 | AX5: =IF(AW5<3,"BAJO",IF(AW5<4,"BASICO",IF(AW5<4.5,"ALTO",IF(AW50<=5,"SUPERIOR")))) -> BAJO | AY5: 1 | AZ5: 4 | BA5: 4 | BB5: 4 | BC5: =((AZ5*0.3)+(BA5*0.4)+(BB5*0.3)) -> 4 | BD5: =IF(BC5<3,"BAJO",IF(BC5<4,"BASICO",IF(BC5<4.5,"ALTO",IF(BC5<=5,"SUPERIOR")))) -> ALTO | BE5: 2 | BF5: 3.5 | BG5: 3.6 | BH5: 3.7 | BI5: =((BF5*0.3)+(BG5*0.4)+(BH5*0.3)) -> 3.6 | BJ5: =IF(BI5<3,"BAJO",IF(BI5<4,"BASICO",IF(BI5<4.5,"ALTO",IF(BI5<=5,"SUPERIOR")))) -> BASICO | BK5: 1 | BL5: 3.4 | BM5: 3.5 | BN5: 3.6 | BO5: =((BL5*0.3)+(BM5*0.4)+(BN5*0.3)) -> 3.5 | BP5: =IF(BO5<3,"BAJO",IF(BO5<4,"BASICO",IF(BO5<4.5,"ALTO",IF(BO5<=5,"SUPERIOR")))) -> BASICO | BQ5: 1 | BR5: 3.4 | BS5: 3.5 | BT5: 3.6 | BU5: =((BR5*0.3)+(BS5*0.4)+(BT5*0.3)) -> 3.5 | BV5: =IF(BU5<3,"BAJO",IF(BU5<4,"BASICO",IF(BU5<4.5,"ALTO",IF(BU5<=5,"SUPERIOR")))) -> BASICO | BW5: 1 | BX5: 3.5 | BY5: 3.5 | BZ5: 3.5 | CA5: =((BX5*0.3)+(BY5*0.4)+(BZ5*0.3)) -> 3.5 | CB5: =IF(CA5<3,"BAJO",IF(CA5<4,"BASICO",IF(CA5<4.5,"ALTO",IF(CA5<=5,"SUPERIOR")))) -> BASICO | CC5: 1 | CD5: 4 | CE5: 4.2 | CF5: 4.2 | CG5: =((CD5*0.3)+(CE5*0.4)+(CF5*0.3)) -> 4.14 | CH5: =IF(CG5<3,"BAJO",IF(CG5<4,"BASICO",IF(CG5<4.5,"ALTO",IF(CG5<=5,"SUPERIOR")))) -> ALTO | CI5: 1 | CJ5: 4 | CK5: 4 | CL5: 4 | CM5: =((CJ5*0.3)+(CK5*0.4)+(CL5*0.3)) -> 4 | CN5: =IF(CM5<3,"BAJO",IF(CM5<4,"BASICO",IF(CM5<4.5,"ALTO",IF(CM5<=5,"SUPERIOR")))) -> ALTO | CO5: 1 | CP5: 3.8 | CQ5: 3.8 | CR5: 3.8 | CS5: =((CP5*0.3)+(CQ5*0.4)+(CR5*0.3)) -> 3.8 | CT5: =IF(CS5<3,"BAJO",IF(CS5<4,"BASICO",IF(CS5<4.5,"ALTO",IF(CS5<=5,"SUPERIOR")))) -> BASICO | CU5: 2 | CV5: 2 | CW5: 2 | CX5: 2 | CY5: =((CV5*0.3)+(CW5*0.4)+(CX5*0.3)) -> 2 | CZ5: =IF(CY5<3,"BAJO",IF(CY5<4,"BASICO",IF(CY5<4.5,"ALTO",IF(CY5<=5,"SUPERIOR")))) -> BAJO | DA5: 2 | DB5: 2 | DC5: 2 | DD5: 3.5 | DE5: =((DB5*0.3)+(DC5*0.4)+(DD5*0.3)) -> 2.45 | DF5: =IF(DE5<2.95,"BAJO",IF(DE5<3.95,"BASICO",IF(DE5<4.45,"ALTO",IF(DE5<=5,"SUPERIOR")))) -> BAJO | DG5: 0 | DI5: =IF(DH5<3,"BAJO",IF(DH5<4,"BASICO",IF(DH5<4.5,"ALTO",IF(DH5<=5,"SUPERIOR")))) -> BAJO | DJ5: =AVERAGE(M5,Y5,AE5,AK5,AW5,BC5,BI5,BO5,CA5,DE5,DH5,CY5,CS5,CM5,CG5,AQ5,S5) -> 3.449375 | DK5: =$DK$2 -> Comprende el concepto de números reales, su relación de orden y las propiedades de sus operaciones, así como las relaciones de semejanza y congruencia de distintas figuras geométricas. | DL5: =DL4 -> Aplica correctamente las propiedades de las operaciones de números reales y expresiones algebraicas en la resolución de problemas. | DM5: =DM4 -> Valora el uso del pensamiento lógico a la hora de plantear y resolver problemas de las matemáticas y de la vida cotidiana. | DN5: =DN4 -> Reconoce y clasifica variables aleatorias, comprendiendo sus tipos y características; además, interpreta la información presentada en tablas de frecuencias y diagramas estadísticos, explicando su significado en contextos diversos. | DO5: =DO4 -> Organiza y analiza datos mediante la construcción de tablas de frecuencias y diagramas estadísticos, identificando variables aleatorias y utilizando estas representaciones para resolver situaciones problema. | DP5: =DP4 -> Muestra disposición y responsabilidad en el manejo y análisis de datos, participando activamente en actividades individuales y colaborativas, y comunicando información estadística con claridad y sentido crítico. | DQ5: =DQ4 -> Analiza las características de la literatura prehispánica y la literatura del descubrimiento y la conquista en Colombia identificando sus elementos fundamentales y su impacto en la cultura y el lenguaje actual. | DR5: =DR4 -> Realiza comprensión lectora cuando analiza un texto desde el discurso de la Enunciación e identifica la función de cada uno de sus componentes. Responde preguntas en los tres niveles de lectura a una leyenda del Caribe. | DS5: =DS4 -> Muestra disposición para participar activamente en las clases, promoviendo el respeto por las ideas ajenas y reconociendo la importancia de la precisión como una herramienta clave para una comunicación | ... FJ5: =FJ4 -> Identifica y reconoce sus pricipales deberes y derechos dentro y fuera de la Institución educativa.
A6: 5 | B6: CABALLERO REALES HARETH JANOVIS | C6: 1047053184 | D6: 8°A | E6: Yenis María Duncan Ramirez | F6: Mañana | G6: PRIMERO | H6: 2026 | I6: 4 | J6: 3.2 | K6: 3.4 | L6: 3.6 | M6: =((J6*0.3)+(K6*0.4)+(L6*0.3)) -> 3.4 | N6: =IF(M6<3,"BAJO",IF(M6<4,"BASICO",IF(M6<4.5,"ALTO",IF(M6<=5,"SUPERIOR")))) -> BASICO | O6: 1 | P6: 4.1 | Q6: 4.1 | R6: 4.1 | S6: =((P6*0.3)+(Q6*0.4)+(R6*0.3)) -> 4.1 | T6: =IF(S6<3,"BAJO",IF(S6<4,"BASICO",IF(S6<4.5,"ALTO",IF(S6<=5,"SUPERIOR")))) -> ALTO | U6: 4 | V6: 3.3 | W6: 3.5 | X6: 3.8 | Y6: =((V6*0.3)+(W6*0.4)+(X6*0.3)) -> 3.53 | Z6: =IF(Y6<3,"BAJO",IF(Y6<4,"BASICO",IF(Y6<4.5,"ALTO",IF(Y6<=5,"SUPERIOR")))) -> BASICO | AA6: 1 | AB6: 2.8 | AC6: 2.8 | AD6: 2.8 | AE6: =((AB6*0.3)+(AC6*0.4)+(AD6*0.3)) -> 2.8 | AF6: =IF(AE6<3,"BAJO",IF(AE6<4,"BASICO",IF(AE6<4.5,"ALTO",IF(AE6<=5,"SUPERIOR")))) -> BAJO | AG6: 2 | AH6: 3.5 | AI6: 3.5 | AJ6: 3.5 | AK6: =((AH6*0.3)+(AI6*0.4)+(AJ6*0.3)) -> 3.5 | AL6: =IF(AK6<3,"BAJO",IF(AK6<4,"BASICO",IF(AK6<4.5,"ALTO",IF(AK6<=5,"SUPERIOR")))) -> BASICO | AM6: 1 | AN6: 3.5 | AO6: 3.5 | AP6: 3.5 | AQ6: =((AN6*0.3)+(AO6*0.4)+(AP6*0.3)) -> 3.5 | AR6: =IF(AQ6<3,"BAJO",IF(AQ6<4,"BASICO",IF(AQ6<4.5,"ALTO",IF(AQ6<=5,"SUPERIOR")))) -> BASICO | AS6: 4 | AT6: 2.5 | AU6: 2.5 | AV6: 2.5 | AW6: =((AT6*0.3)+(AU6*0.4)+(AV6*0.3)) -> 2.5 | AX6: =IF(AW6<3,"BAJO",IF(AW6<4,"BASICO",IF(AW6<4.5,"ALTO",IF(AW51<=5,"SUPERIOR")))) -> BAJO | AY6: 1 | AZ6: 3.5 | BA6: 3.5 | BB6: 3.5 | BC6: =((AZ6*0.3)+(BA6*0.4)+(BB6*0.3)) -> 3.5 | BD6: =IF(BC6<3,"BAJO",IF(BC6<4,"BASICO",IF(BC6<4.5,"ALTO",IF(BC6<=5,"SUPERIOR")))) -> BASICO | BE6: 2 | BF6: 3.5 | BG6: 3.6 | BH6: 3.8 | BI6: =((BF6*0.3)+(BG6*0.4)+(BH6*0.3)) -> 3.63 | BJ6: =IF(BI6<3,"BAJO",IF(BI6<4,"BASICO",IF(BI6<4.5,"ALTO",IF(BI6<=5,"SUPERIOR")))) -> BASICO | BK6: 1 | BL6: 3.5 | BM6: 3.6 | BN6: 3.8 | BO6: =((BL6*0.3)+(BM6*0.4)+(BN6*0.3)) -> 3.63 | BP6: =IF(BO6<3,"BAJO",IF(BO6<4,"BASICO",IF(BO6<4.5,"ALTO",IF(BO6<=5,"SUPERIOR")))) -> BASICO | BQ6: 1 | BR6: 3.5 | BS6: 3.6 | BT6: 3.8 | BU6: =((BR6*0.3)+(BS6*0.4)+(BT6*0.3)) -> 3.63 | BV6: =IF(BU6<3,"BAJO",IF(BU6<4,"BASICO",IF(BU6<4.5,"ALTO",IF(BU6<=5,"SUPERIOR")))) -> BASICO | BW6: 1 | BX6: 3.5 | BY6: 3.5 | BZ6: 3.5 | CA6: =((BX6*0.3)+(BY6*0.4)+(BZ6*0.3)) -> 3.5 | CB6: =IF(CA6<3,"BAJO",IF(CA6<4,"BASICO",IF(CA6<4.5,"ALTO",IF(CA6<=5,"SUPERIOR")))) -> BASICO | CC6: 1 | CD6: 4 | CE6: 4.2 | CF6: 4.2 | CG6: =((CD6*0.3)+(CE6*0.4)+(CF6*0.3)) -> 4.14 | CH6: =IF(CG6<3,"BAJO",IF(CG6<4,"BASICO",IF(CG6<4.5,"ALTO",IF(CG6<=5,"SUPERIOR")))) -> ALTO | CI6: 1 | CJ6: 4.5 | CK6: 4.5 | CL6: 4.3 | CM6: =((CJ6*0.3)+(CK6*0.4)+(CL6*0.3)) -> 4.44 | CN6: =IF(CM6<3,"BAJO",IF(CM6<4,"BASICO",IF(CM6<4.5,"ALTO",IF(CM6<=5,"SUPERIOR")))) -> ALTO | CO6: 1 | CP6: 3.5 | CQ6: 3.5 | CR6: 3.5 | CS6: =((CP6*0.3)+(CQ6*0.4)+(CR6*0.3)) -> 3.5 | CT6: =IF(CS6<3,"BAJO",IF(CS6<4,"BASICO",IF(CS6<4.5,"ALTO",IF(CS6<=5,"SUPERIOR")))) -> BASICO | CU6: 2 | CV6: 4 | CW6: 4 | CX6: 4 | CY6: =((CV6*0.3)+(CW6*0.4)+(CX6*0.3)) -> 4 | CZ6: =IF(CY6<3,"BAJO",IF(CY6<4,"BASICO",IF(CY6<4.5,"ALTO",IF(CY6<=5,"SUPERIOR")))) -> ALTO | DA6: 2 | DB6: 4 | DC6: 4 | DD6: 4 | DE6: =((DB6*0.3)+(DC6*0.4)+(DD6*0.3)) -> 4 | DF6: =IF(DE6<2.95,"BAJO",IF(DE6<3.95,"BASICO",IF(DE6<4.45,"ALTO",IF(DE6<=5,"SUPERIOR")))) -> ALTO | DG6: 0 | DI6: =IF(DH6<3,"BAJO",IF(DH6<4,"BASICO",IF(DH6<4.5,"ALTO",IF(DH6<=5,"SUPERIOR")))) -> BAJO | DJ6: =AVERAGE(M6,Y6,AE6,AK6,AW6,BC6,BI6,BO6,CA6,DE6,DH6,CY6,CS6,CM6,CG6,AQ6,S6) -> 3.604375 | DK6: =$DK$2 -> Comprende el concepto de números reales, su relación de orden y las propiedades de sus operaciones, así como las relaciones de semejanza y congruencia de distintas figuras geométricas. | DL6: =DL5 -> Aplica correctamente las propiedades de las operaciones de números reales y expresiones algebraicas en la resolución de problemas. | DM6: =DM5 -> Valora el uso del pensamiento lógico a la hora de plantear y resolver problemas de las matemáticas y de la vida cotidiana. | DN6: =DN5 -> Reconoce y clasifica variables aleatorias, comprendiendo sus tipos y características; además, interpreta la información presentada en tablas de frecuencias y diagramas estadísticos, explicando su significado en contextos diversos. | DO6: =DO5 -> Organiza y analiza datos mediante la construcción de tablas de frecuencias y diagramas estadísticos, identificando variables aleatorias y utilizando estas representaciones para resolver situaciones problema. | DP6: =DP5 -> Muestra disposición y responsabilidad en el manejo y análisis de datos, participando activamente en actividades individuales y colaborativas, y comunicando información estadística con claridad y sentido crítico. | DQ6: =DQ5 -> Analiza las características de la literatura prehispánica y la literatura del descubrimiento y la conquista en Colombia identificando sus elementos fundamentales y su impacto en la cultura y el lenguaje actual. | DR6: =DR5 -> Realiza comprensión lectora cuando analiza un texto desde el discurso de la Enunciación e identifica la función de cada uno de sus componentes. Responde preguntas en los tres niveles de lectura a una leyenda del Caribe. | DS6: =DS5 -> Muestra disposición para participar activamente en las clases, promoviendo el respeto por las ideas ajenas y reconociendo la importancia de la precisión como una herramienta clave para una comunicación | ... FJ6: =FJ5 -> Identifica y reconoce sus pricipales deberes y derechos dentro y fuera de la Institución educativa.
A7: 6 | B7: CAMARGO TOLOZA ELIAS JESUS | C7: 1044642358 | D7: 8°A | E7: Yenis María Duncan Ramirez | F7: Mañana | G7: PRIMERO | H7: 2026 | I7: 4 | J7: 2.9 | K7: 3 | L7: 3.1 | M7: =((J7*0.3)+(K7*0.4)+(L7*0.3)) -> 3 | N7: =IF(M7<3,"BAJO",IF(M7<4,"BASICO",IF(M7<4.5,"ALTO",IF(M7<=5,"SUPERIOR")))) -> BASICO | O7: 1 | P7: 4.3 | Q7: 4.3 | R7: 4.3 | S7: =((P7*0.3)+(Q7*0.4)+(R7*0.3)) -> 4.3 | T7: =IF(S7<3,"BAJO",IF(S7<4,"BASICO",IF(S7<4.5,"ALTO",IF(S7<=5,"SUPERIOR")))) -> ALTO | U7: 4 | V7: 3.8 | W7: 3.8 | X7: 3.3 | Y7: =((V7*0.3)+(W7*0.4)+(X7*0.3)) -> 3.65 | Z7: =IF(Y7<3,"BAJO",IF(Y7<4,"BASICO",IF(Y7<4.5,"ALTO",IF(Y7<=5,"SUPERIOR")))) -> BASICO | AA7: 1 | AB7: 2.6 | AC7: 2.6 | AD7: 2.6 | AE7: =((AB7*0.3)+(AC7*0.4)+(AD7*0.3)) -> 2.6 | AF7: =IF(AE7<3,"BAJO",IF(AE7<4,"BASICO",IF(AE7<4.5,"ALTO",IF(AE7<=5,"SUPERIOR")))) -> BAJO | AG7: 2 | AH7: 2.5 | AI7: 3 | AJ7: 3 | AK7: =((AH7*0.3)+(AI7*0.4)+(AJ7*0.3)) -> 2.85 | AL7: =IF(AK7<3,"BAJO",IF(AK7<4,"BASICO",IF(AK7<4.5,"ALTO",IF(AK7<=5,"SUPERIOR")))) -> BAJO | AM7: 1 | AN7: 2.5 | AO7: 3 | AP7: 3 | AQ7: =((AN7*0.3)+(AO7*0.4)+(AP7*0.3)) -> 2.85 | AR7: =IF(AQ7<3,"BAJO",IF(AQ7<4,"BASICO",IF(AQ7<4.5,"ALTO",IF(AQ7<=5,"SUPERIOR")))) -> BAJO | AS7: 4 | AT7: 3.5 | AU7: 3.5 | AV7: 3.5 | AW7: =((AT7*0.3)+(AU7*0.4)+(AV7*0.3)) -> 3.5 | AX7: =IF(AW7<3,"BAJO",IF(AW7<4,"BASICO",IF(AW7<4.5,"ALTO",IF(AW52<=5,"SUPERIOR")))) -> BASICO | AY7: 1 | AZ7: 3.5 | BA7: 3 | BB7: 3 | BC7: =((AZ7*0.3)+(BA7*0.4)+(BB7*0.3)) -> 3.15 | BD7: =IF(BC7<3,"BAJO",IF(BC7<4,"BASICO",IF(BC7<4.5,"ALTO",IF(BC7<=5,"SUPERIOR")))) -> BASICO | BE7: 2 | BF7: 3.3 | BG7: 3.2 | BH7: 3.4 | BI7: =((BF7*0.3)+(BG7*0.4)+(BH7*0.3)) -> 3.29 | BJ7: =IF(BI7<3,"BAJO",IF(BI7<4,"BASICO",IF(BI7<4.5,"ALTO",IF(BI7<=5,"SUPERIOR")))) -> BASICO | BK7: 1 | BL7: 3.2 | BM7: 3.3 | BN7: 3.4 | BO7: =((BL7*0.3)+(BM7*0.4)+(BN7*0.3)) -> 3.3 | BP7: =IF(BO7<3,"BAJO",IF(BO7<4,"BASICO",IF(BO7<4.5,"ALTO",IF(BO7<=5,"SUPERIOR")))) -> BASICO | BQ7: 1 | BR7: 3.2 | BS7: 3.3 | BT7: 3.4 | BU7: =((BR7*0.3)+(BS7*0.4)+(BT7*0.3)) -> 3.3 | BV7: =IF(BU7<3,"BAJO",IF(BU7<4,"BASICO",IF(BU7<4.5,"ALTO",IF(BU7<=5,"SUPERIOR")))) -> BASICO | BW7: 1 | BX7: 3.4 | BY7: 3.4 | BZ7: 3.4 | CA7: =((BX7*0.3)+(BY7*0.4)+(BZ7*0.3)) -> 3.4 | CB7: =IF(CA7<3,"BAJO",IF(CA7<4,"BASICO",IF(CA7<4.5,"ALTO",IF(CA7<=5,"SUPERIOR")))) -> BASICO | CC7: 1 | CD7: 3.5 | CE7: 3.4 | CF7: 3.4 | CG7: =((CD7*0.3)+(CE7*0.4)+(CF7*0.3)) -> 3.43 | CH7: =IF(CG7<3,"BAJO",IF(CG7<4,"BASICO",IF(CG7<4.5,"ALTO",IF(CG7<=5,"SUPERIOR")))) -> BASICO | CI7: 1 | CJ7: 4.5 | CK7: 4 | CL7: 3.5 | CM7: =((CJ7*0.3)+(CK7*0.4)+(CL7*0.3)) -> 4 | CN7: =IF(CM7<3,"BAJO",IF(CM7<4,"BASICO",IF(CM7<4.5,"ALTO",IF(CM7<=5,"SUPERIOR")))) -> ALTO | CO7: 1 | CP7: 3.8 | CQ7: 3.8 | CR7: 3.8 | CS7: =((CP7*0.3)+(CQ7*0.4)+(CR7*0.3)) -> 3.8 | CT7: =IF(CS7<3,"BAJO",IF(CS7<4,"BASICO",IF(CS7<4.5,"ALTO",IF(CS7<=5,"SUPERIOR")))) -> BASICO | CU7: 2 | CV7: 4 | CW7: 4 | CX7: 4 | CY7: =((CV7*0.3)+(CW7*0.4)+(CX7*0.3)) -> 4 | CZ7: =IF(CY7<3,"BAJO",IF(CY7<4,"BASICO",IF(CY7<4.5,"ALTO",IF(CY7<=5,"SUPERIOR")))) -> ALTO | DA7: 2 | DB7: 2 | DC7: 2 | DD7: 3 | DE7: =((DB7*0.3)+(DC7*0.4)+(DD7*0.3)) -> 2.3 | DF7: =IF(DE7<2.95,"BAJO",IF(DE7<3.95,"BASICO",IF(DE7<4.45,"ALTO",IF(DE7<=5,"SUPERIOR")))) -> BAJO | DG7: 0 | DI7: =IF(DH7<3,"BAJO",IF(DH7<4,"BASICO",IF(DH7<4.5,"ALTO",IF(DH7<=5,"SUPERIOR")))) -> BAJO | DJ7: =AVERAGE(M7,Y7,AE7,AK7,AW7,BC7,BI7,BO7,CA7,DE7,DH7,CY7,CS7,CM7,CG7,AQ7,S7) -> 3.33875 | DK7: =$DK$2 -> Comprende el concepto de números reales, su relación de orden y las propiedades de sus operaciones, así como las relaciones de semejanza y congruencia de distintas figuras geométricas. | DL7: =DL6 -> Aplica correctamente las propiedades de las operaciones de números reales y expresiones algebraicas en la resolución de problemas. | DM7: =DM6 -> Valora el uso del pensamiento lógico a la hora de plantear y resolver problemas de las matemáticas y de la vida cotidiana. | DN7: =DN6 -> Reconoce y clasifica variables aleatorias, comprendiendo sus tipos y características; además, interpreta la información presentada en tablas de frecuencias y diagramas estadísticos, explicando su significado en contextos diversos. | DO7: =DO6 -> Organiza y analiza datos mediante la construcción de tablas de frecuencias y diagramas estadísticos, identificando variables aleatorias y utilizando estas representaciones para resolver situaciones problema. | DP7: =DP6 -> Muestra disposición y responsabilidad en el manejo y análisis de datos, participando activamente en actividades individuales y colaborativas, y comunicando información estadística con claridad y sentido crítico. | DQ7: =DQ6 -> Analiza las características de la literatura prehispánica y la literatura del descubrimiento y la conquista en Colombia identificando sus elementos fundamentales y su impacto en la cultura y el lenguaje actual. | DR7: =DR6 -> Realiza comprensión lectora cuando analiza un texto desde el discurso de la Enunciación e identifica la función de cada uno de sus componentes. Responde preguntas en los tres niveles de lectura a una leyenda del Caribe. | DS7: =DS6 -> Muestra disposición para participar activamente en las clases, promoviendo el respeto por las ideas ajenas y reconociendo la importancia de la precisión como una herramienta clave para una comunicación | ... FJ7: =FJ6 -> Identifica y reconoce sus pricipales deberes y derechos dentro y fuera de la Institución educativa.
A8: 7 | B8: CAMPO CABALLERO KARLA ANDREA | C8: 1044650380 | D8: 8°A | E8: Yenis María Duncan Ramirez | F8: Mañana | G8: PRIMERO | H8: 2026 | I8: 4 | J8: 4 | K8: 4 | L8: 4 | M8: =((J8*0.3)+(K8*0.4)+(L8*0.3)) -> 4 | N8: =IF(M8<3,"BAJO",IF(M8<4,"BASICO",IF(M8<4.5,"ALTO",IF(M8<=5,"SUPERIOR")))) -> ALTO | O8: 1 | P8: 4.8 | Q8: 4.8 | R8: 4.8 | S8: =((P8*0.3)+(Q8*0.4)+(R8*0.3)) -> 4.8 | T8: =IF(S8<3,"BAJO",IF(S8<4,"BASICO",IF(S8<4.5,"ALTO",IF(S8<=5,"SUPERIOR")))) -> SUPERIOR | U8: 4 | V8: 4.7 | W8: 3.5 | X8: 4 | Y8: =((V8*0.3)+(W8*0.4)+(X8*0.3)) -> 4.01 | Z8: =IF(Y8<3,"BAJO",IF(Y8<4,"BASICO",IF(Y8<4.5,"ALTO",IF(Y8<=5,"SUPERIOR")))) -> ALTO | AA8: 1 | AB8: 4.5 | AC8: 4.5 | AD8: 4.5 | AE8: =((AB8*0.3)+(AC8*0.4)+(AD8*0.3)) -> 4.5 | AF8: =IF(AE8<3,"BAJO",IF(AE8<4,"BASICO",IF(AE8<4.5,"ALTO",IF(AE8<=5,"SUPERIOR")))) -> SUPERIOR | AG8: 2 | AH8: 4.8 | AI8: 4.8 | AJ8: 4.8 | AK8: =((AH8*0.3)+(AI8*0.4)+(AJ8*0.3)) -> 4.8 | AL8: =IF(AK8<3,"BAJO",IF(AK8<4,"BASICO",IF(AK8<4.5,"ALTO",IF(AK8<=5,"SUPERIOR")))) -> SUPERIOR | AM8: 1 | AN8: 4.8 | AO8: 4.8 | AP8: 4.8 | AQ8: =((AN8*0.3)+(AO8*0.4)+(AP8*0.3)) -> 4.8 | AR8: =IF(AQ8<3,"BAJO",IF(AQ8<4,"BASICO",IF(AQ8<4.5,"ALTO",IF(AQ8<=5,"SUPERIOR")))) -> SUPERIOR | AS8: 4 | AT8: 3.5 | AU8: 3.5 | AV8: 3.5 | AW8: =((AT8*0.3)+(AU8*0.4)+(AV8*0.3)) -> 3.5 | AX8: =IF(AW8<3,"BAJO",IF(AW8<4,"BASICO",IF(AW8<4.5,"ALTO",IF(AW53<=5,"SUPERIOR")))) -> BASICO | AY8: 1 | AZ8: 5 | BA8: 5 | BB8: 5 | BC8: =((AZ8*0.3)+(BA8*0.4)+(BB8*0.3)) -> 5 | BD8: =IF(BC8<3,"BAJO",IF(BC8<4,"BASICO",IF(BC8<4.5,"ALTO",IF(BC8<=5,"SUPERIOR")))) -> SUPERIOR | BE8: 2 | BF8: 4 | BG8: 4.4 | BH8: 4.5 | BI8: =((BF8*0.3)+(BG8*0.4)+(BH8*0.3)) -> 4.31 | BJ8: =IF(BI8<3,"BAJO",IF(BI8<4,"BASICO",IF(BI8<4.5,"ALTO",IF(BI8<=5,"SUPERIOR")))) -> ALTO | BK8: 1 | BL8: 4.3 | BM8: 4.2 | BN8: 4.5 | BO8: =((BL8*0.3)+(BM8*0.4)+(BN8*0.3)) -> 4.32 | BP8: =IF(BO8<3,"BAJO",IF(BO8<4,"BASICO",IF(BO8<4.5,"ALTO",IF(BO8<=5,"SUPERIOR")))) -> ALTO | BQ8: 1 | BR8: 4.4 | BS8: 4.2 | BT8: 4.5 | BU8: =((BR8*0.3)+(BS8*0.4)+(BT8*0.3)) -> 4.35 | BV8: =IF(BU8<3,"BAJO",IF(BU8<4,"BASICO",IF(BU8<4.5,"ALTO",IF(BU8<=5,"SUPERIOR")))) -> ALTO | BW8: 1 | BX8: 4 | BY8: 4 | BZ8: 4 | CA8: =((BX8*0.3)+(BY8*0.4)+(BZ8*0.3)) -> 4 | CB8: =IF(CA8<3,"BAJO",IF(CA8<4,"BASICO",IF(CA8<4.5,"ALTO",IF(CA8<=5,"SUPERIOR")))) -> ALTO | CC8: 1 | CD8: 4 | CE8: 4.2 | CF8: 4.2 | CG8: =((CD8*0.3)+(CE8*0.4)+(CF8*0.3)) -> 4.14 | CH8: =IF(CG8<3,"BAJO",IF(CG8<4,"BASICO",IF(CG8<4.5,"ALTO",IF(CG8<=5,"SUPERIOR")))) -> ALTO | CI8: 1 | CJ8: 4.5 | CK8: 4.5 | CL8: 4.5 | CM8: =((CJ8*0.3)+(CK8*0.4)+(CL8*0.3)) -> 4.5 | CN8: =IF(CM8<3,"BAJO",IF(CM8<4,"BASICO",IF(CM8<4.5,"ALTO",IF(CM8<=5,"SUPERIOR")))) -> SUPERIOR | CO8: 1 | CP8: 5 | CQ8: 5 | CR8: 5 | CS8: =((CP8*0.3)+(CQ8*0.4)+(CR8*0.3)) -> 5 | CT8: =IF(CS8<3,"BAJO",IF(CS8<4,"BASICO",IF(CS8<4.5,"ALTO",IF(CS8<=5,"SUPERIOR")))) -> SUPERIOR | CU8: 2 | CV8: 3.5 | CW8: 3.5 | CX8: 3.5 | CY8: =((CV8*0.3)+(CW8*0.4)+(CX8*0.3)) -> 3.5 | CZ8: =IF(CY8<3,"BAJO",IF(CY8<4,"BASICO",IF(CY8<4.5,"ALTO",IF(CY8<=5,"SUPERIOR")))) -> BASICO | DA8: 2 | DB8: 3.5 | DC8: 3.5 | DD8: 3.8 | DE8: =((DB8*0.3)+(DC8*0.4)+(DD8*0.3)) -> 3.59 | DF8: =IF(DE8<2.95,"BAJO",IF(DE8<3.95,"BASICO",IF(DE8<4.45,"ALTO",IF(DE8<=5,"SUPERIOR")))) -> BASICO | DG8: 0 | DI8: =IF(DH8<3,"BAJO",IF(DH8<4,"BASICO",IF(DH8<4.5,"ALTO",IF(DH8<=5,"SUPERIOR")))) -> BAJO | DJ8: =AVERAGE(M8,Y8,AE8,AK8,AW8,BC8,BI8,BO8,CA8,DE8,DH8,CY8,CS8,CM8,CG8,AQ8,S8) -> 4.298125 | DK8: =$DK$2 -> Comprende el concepto de números reales, su relación de orden y las propiedades de sus operaciones, así como las relaciones de semejanza y congruencia de distintas figuras geométricas. | DL8: =DL7 -> Aplica correctamente las propiedades de las operaciones de números reales y expresiones algebraicas en la resolución de problemas. | DM8: =DM7 -> Valora el uso del pensamiento lógico a la hora de plantear y resolver problemas de las matemáticas y de la vida cotidiana. | DN8: =DN7 -> Reconoce y clasifica variables aleatorias, comprendiendo sus tipos y características; además, interpreta la información presentada en tablas de frecuencias y diagramas estadísticos, explicando su significado en contextos diversos. | DO8: =DO7 -> Organiza y analiza datos mediante la construcción de tablas de frecuencias y diagramas estadísticos, identificando variables aleatorias y utilizando estas representaciones para resolver situaciones problema. | DP8: =DP7 -> Muestra disposición y responsabilidad en el manejo y análisis de datos, participando activamente en actividades individuales y colaborativas, y comunicando información estadística con claridad y sentido crítico. | DQ8: =DQ7 -> Analiza las características de la literatura prehispánica y la literatura del descubrimiento y la conquista en Colombia identificando sus elementos fundamentales y su impacto en la cultura y el lenguaje actual. | DR8: =DR7 -> Realiza comprensión lectora cuando analiza un texto desde el discurso de la Enunciación e identifica la función de cada uno de sus componentes. Responde preguntas en los tres niveles de lectura a una leyenda del Caribe. | DS8: =DS7 -> Muestra disposición para participar activamente en las clases, promoviendo el respeto por las ideas ajenas y reconociendo la importancia de la precisión como una herramienta clave para una comunicación | ... FJ8: =FJ7 -> Identifica y reconoce sus pricipales deberes y derechos dentro y fuera de la Institución educativa.
A9: 8 | B9: CANTILLO PALLARES SOFIA | C9: 1042862727 | D9: 8°A | E9: Yenis María Duncan Ramirez | F9: Mañana | G9: PRIMERO | H9: 2026 | I9: 4 | J9: 3.8 | K9: 4 | L9: 4.2 | M9: =((J9*0.3)+(K9*0.4)+(L9*0.3)) -> 4 | N9: =IF(M9<3,"BAJO",IF(M9<4,"BASICO",IF(M9<4.5,"ALTO",IF(M9<=5,"SUPERIOR")))) -> ALTO | O9: 1 | P9: 4.8 | Q9: 4.8 | R9: 4.8 | S9: =((P9*0.3)+(Q9*0.4)+(R9*0.3)) -> 4.8 | T9: =IF(S9<3,"BAJO",IF(S9<4,"BASICO",IF(S9<4.5,"ALTO",IF(S9<=5,"SUPERIOR")))) -> SUPERIOR | U9: 4 | V9: 5 | W9: 5 | X9: 4.7 | Y9: =((V9*0.3)+(W9*0.4)+(X9*0.3)) -> 4.91 | Z9: =IF(Y9<3,"BAJO",IF(Y9<4,"BASICO",IF(Y9<4.5,"ALTO",IF(Y9<=5,"SUPERIOR")))) -> SUPERIOR | AA9: 1 | AB9: 4.5 | AC9: 4.5 | AD9: 4.5 | AE9: =((AB9*0.3)+(AC9*0.4)+(AD9*0.3)) -> 4.5 | AF9: =IF(AE9<3,"BAJO",IF(AE9<4,"BASICO",IF(AE9<4.5,"ALTO",IF(AE9<=5,"SUPERIOR")))) -> SUPERIOR | AG9: 2 | AH9: 4.8 | AI9: 4.8 | AJ9: 4.8 | AK9: =((AH9*0.3)+(AI9*0.4)+(AJ9*0.3)) -> 4.8 | AL9: =IF(AK9<3,"BAJO",IF(AK9<4,"BASICO",IF(AK9<4.5,"ALTO",IF(AK9<=5,"SUPERIOR")))) -> SUPERIOR | AM9: 1 | AN9: 4.8 | AO9: 4.8 | AP9: 4.8 | AQ9: =((AN9*0.3)+(AO9*0.4)+(AP9*0.3)) -> 4.8 | AR9: =IF(AQ9<3,"BAJO",IF(AQ9<4,"BASICO",IF(AQ9<4.5,"ALTO",IF(AQ9<=5,"SUPERIOR")))) -> SUPERIOR | AS9: 4 | AT9: 3.8 | AU9: 3.8 | AV9: 3.8 | AW9: =((AT9*0.3)+(AU9*0.4)+(AV9*0.3)) -> 3.8 | AX9: =IF(AW9<3,"BAJO",IF(AW9<4,"BASICO",IF(AW9<4.5,"ALTO",IF(AW54<=5,"SUPERIOR")))) -> BASICO | AY9: 1 | AZ9: 4.5 | BA9: 4.5 | BB9: 4.5 | BC9: =((AZ9*0.3)+(BA9*0.4)+(BB9*0.3)) -> 4.5 | BD9: =IF(BC9<3,"BAJO",IF(BC9<4,"BASICO",IF(BC9<4.5,"ALTO",IF(BC9<=5,"SUPERIOR")))) -> SUPERIOR | BE9: 2 | BF9: 4 | BG9: 4.5 | BH9: 4.4 | BI9: =((BF9*0.3)+(BG9*0.4)+(BH9*0.3)) -> 4.32 | BJ9: =IF(BI9<3,"BAJO",IF(BI9<4,"BASICO",IF(BI9<4.5,"ALTO",IF(BI9<=5,"SUPERIOR")))) -> ALTO | BK9: 1 | BL9: 4.5 | BM9: 4 | BN9: 4.4 | BO9: =((BL9*0.3)+(BM9*0.4)+(BN9*0.3)) -> 4.27 | BP9: =IF(BO9<3,"BAJO",IF(BO9<4,"BASICO",IF(BO9<4.5,"ALTO",IF(BO9<=5,"SUPERIOR")))) -> ALTO | BQ9: 1 | BR9: 4 | BS9: 4.4 | BT9: 4.5 | BU9: =((BR9*0.3)+(BS9*0.4)+(BT9*0.3)) -> 4.31 | BV9: =IF(BU9<3,"BAJO",IF(BU9<4,"BASICO",IF(BU9<4.5,"ALTO",IF(BU9<=5,"SUPERIOR")))) -> ALTO | BW9: 1 | BX9: 4 | BY9: 4.5 | BZ9: 4.4 | CA9: =((BX9*0.3)+(BY9*0.4)+(BZ9*0.3)) -> 4.32 | CB9: =IF(CA9<3,"BAJO",IF(CA9<4,"BASICO",IF(CA9<4.5,"ALTO",IF(CA9<=5,"SUPERIOR")))) -> ALTO | CC9: 1 | CD9: 4 | CE9: 4.2 | CF9: 4.2 | CG9: =((CD9*0.3)+(CE9*0.4)+(CF9*0.3)) -> 4.14 | CH9: =IF(CG9<3,"BAJO",IF(CG9<4,"BASICO",IF(CG9<4.5,"ALTO",IF(CG9<=5,"SUPERIOR")))) -> ALTO | CI9: 1 | CJ9: 4.4 | CK9: 4.4 | CL9: 4.4 | CM9: =((CJ9*0.3)+(CK9*0.4)+(CL9*0.3)) -> 4.4 | CN9: =IF(CM9<3,"BAJO",IF(CM9<4,"BASICO",IF(CM9<4.5,"ALTO",IF(CM9<=5,"SUPERIOR")))) -> ALTO | CO9: 1 | CP9: 5 | CQ9: 5 | CR9: 5 | CS9: =((CP9*0.3)+(CQ9*0.4)+(CR9*0.3)) -> 5 | CT9: =IF(CS9<3,"BAJO",IF(CS9<4,"BASICO",IF(CS9<4.5,"ALTO",IF(CS9<=5,"SUPERIOR")))) -> SUPERIOR | CU9: 2 | CV9: 3.8 | CW9: 3.8 | CX9: 3.8 | CY9: =((CV9*0.3)+(CW9*0.4)+(CX9*0.3)) -> 3.8 | CZ9: =IF(CY9<3,"BAJO",IF(CY9<4,"BASICO",IF(CY9<4.5,"ALTO",IF(CY9<=5,"SUPERIOR")))) -> BASICO | DA9: 2 | DB9: 3.5 | DC9: 3.5 | DD9: 3.5 | DE9: =((DB9*0.3)+(DC9*0.4)+(DD9*0.3)) -> 3.5 | DF9: =IF(DE9<2.95,"BAJO",IF(DE9<3.95,"BASICO",IF(DE9<4.45,"ALTO",IF(DE9<=5,"SUPERIOR")))) -> BASICO | DG9: 0 | DI9: =IF(DH9<3,"BAJO",IF(DH9<4,"BASICO",IF(DH9<4.5,"ALTO",IF(DH9<=5,"SUPERIOR")))) -> BAJO | DJ9: =AVERAGE(M9,Y9,AE9,AK9,AW9,BC9,BI9,BO9,CA9,DE9,DH9,CY9,CS9,CM9,CG9,AQ9,S9) -> 4.36625 | DK9: =$DK$2 -> Comprende el concepto de números reales, su relación de orden y las propiedades de sus operaciones, así como las relaciones de semejanza y congruencia de distintas figuras geométricas. | DL9: =DL8 -> Aplica correctamente las propiedades de las operaciones de números reales y expresiones algebraicas en la resolución de problemas. | DM9: =DM8 -> Valora el uso del pensamiento lógico a la hora de plantear y resolver problemas de las matemáticas y de la vida cotidiana. | DN9: =DN8 -> Reconoce y clasifica variables aleatorias, comprendiendo sus tipos y características; además, interpreta la información presentada en tablas de frecuencias y diagramas estadísticos, explicando su significado en contextos diversos. | DO9: =DO8 -> Organiza y analiza datos mediante la construcción de tablas de frecuencias y diagramas estadísticos, identificando variables aleatorias y utilizando estas representaciones para resolver situaciones problema. | DP9: =DP8 -> Muestra disposición y responsabilidad en el manejo y análisis de datos, participando activamente en actividades individuales y colaborativas, y comunicando información estadística con claridad y sentido crítico. | DQ9: =DQ8 -> Analiza las características de la literatura prehispánica y la literatura del descubrimiento y la conquista en Colombia identificando sus elementos fundamentales y su impacto en la cultura y el lenguaje actual. | DR9: =DR8 -> Realiza comprensión lectora cuando analiza un texto desde el discurso de la Enunciación e identifica la función de cada uno de sus componentes. Responde preguntas en los tres niveles de lectura a una leyenda del Caribe. | DS9: =DS8 -> Muestra disposición para participar activamente en las clases, promoviendo el respeto por las ideas ajenas y reconociendo la importancia de la precisión como una herramienta clave para una comunicación | ... FJ9: =FJ8 -> Identifica y reconoce sus pricipales deberes y derechos dentro y fuera de la Institución educativa.
A10: 9 | B10: CARDENAS SUAREZ DARIS MILENA | C10: 1143146254 | D10: 8°A | E10: Yenis María Duncan Ramirez | F10: Mañana | G10: PRIMERO | H10: 2026 | I10: 4 | J10: 3 | K10: 3.2 | L10: 3.4 | M10: =((J10*0.3)+(K10*0.4)+(L10*0.3)) -> 3.2 | N10: =IF(M10<3,"BAJO",IF(M10<4,"BASICO",IF(M10<4.5,"ALTO",IF(M10<=5,"SUPERIOR")))) -> BASICO | O10: 1 | P10: 3.3 | Q10: 3.3 | R10: 3.3 | S10: =((P10*0.3)+(Q10*0.4)+(R10*0.3)) -> 3.3 | T10: =IF(S10<3,"BAJO",IF(S10<4,"BASICO",IF(S10<4.5,"ALTO",IF(S10<=5,"SUPERIOR")))) -> BASICO | U10: 4 | V10: 2.8 | W10: 2.5 | X10: 3.3 | Y10: =((V10*0.3)+(W10*0.4)+(X10*0.3)) -> 2.83 | Z10: =IF(Y10<3,"BAJO",IF(Y10<4,"BASICO",IF(Y10<4.5,"ALTO",IF(Y10<=5,"SUPERIOR")))) -> BAJO | AA10: 1 | AB10: 2.4 | AC10: 2.4 | AD10: 2.4 | AE10: =((AB10*0.3)+(AC10*0.4)+(AD10*0.3)) -> 2.4 | AF10: =IF(AE10<3,"BAJO",IF(AE10<4,"BASICO",IF(AE10<4.5,"ALTO",IF(AE10<=5,"SUPERIOR")))) -> BAJO | AG10: 2 | AH10: 2.5 | AI10: 3.5 | AJ10: 3.5 | AK10: =((AH10*0.3)+(AI10*0.4)+(AJ10*0.3)) -> 3.2 | AL10: =IF(AK10<3,"BAJO",IF(AK10<4,"BASICO",IF(AK10<4.5,"ALTO",IF(AK10<=5,"SUPERIOR")))) -> BASICO | AM10: 1 | AN10: 2.5 | AO10: 3.5 | AP10: 3.5 | AQ10: =((AN10*0.3)+(AO10*0.4)+(AP10*0.3)) -> 3.2 | AR10: =IF(AQ10<3,"BAJO",IF(AQ10<4,"BASICO",IF(AQ10<4.5,"ALTO",IF(AQ10<=5,"SUPERIOR")))) -> BASICO | AS10: 4 | AT10: 2 | AU10: 2 | AV10: 2 | AW10: =((AT10*0.3)+(AU10*0.4)+(AV10*0.3)) -> 2 | AX10: =IF(AW10<3,"BAJO",IF(AW10<4,"BASICO",IF(AW10<4.5,"ALTO",IF(AW55<=5,"SUPERIOR")))) -> BAJO | AY10: 1 | AZ10: 3.8 | BA10: 3.5 | BC10: =((AZ10*0.3)+(BA10*0.4)+(BB10*0.3)) -> 2.54 | BD10: =IF(BC10<3,"BAJO",IF(BC10<4,"BASICO",IF(BC10<4.5,"ALTO",IF(BC10<=5,"SUPERIOR")))) -> BAJO | BE10: 2 | BF10: 2.5 | BG10: 2.5 | BH10: 2.5 | BI10: =((BF10*0.3)+(BG10*0.4)+(BH10*0.3)) -> 2.5 | BJ10: =IF(BI10<3,"BAJO",IF(BI10<4,"BASICO",IF(BI10<4.5,"ALTO",IF(BI10<=5,"SUPERIOR")))) -> BAJO | BK10: 1 | BL10: 2.5 | BM10: 2.5 | BN10: 2.5 | BO10: =((BL10*0.3)+(BM10*0.4)+(BN10*0.3)) -> 2.5 | BP10: =IF(BO10<3,"BAJO",IF(BO10<4,"BASICO",IF(BO10<4.5,"ALTO",IF(BO10<=5,"SUPERIOR")))) -> BAJO | BQ10: 1 | BR10: 2.5 | BS10: 2.5 | BT10: 2.5 | BU10: =((BR10*0.3)+(BS10*0.4)+(BT10*0.3)) -> 2.5 | BV10: =IF(BU10<3,"BAJO",IF(BU10<4,"BASICO",IF(BU10<4.5,"ALTO",IF(BU10<=5,"SUPERIOR")))) -> BAJO | BW10: 1 | BX10: 2 | BY10: 2 | BZ10: 2 | CA10: =((BX10*0.3)+(BY10*0.4)+(BZ10*0.3)) -> 2 | CB10: =IF(CA10<3,"BAJO",IF(CA10<4,"BASICO",IF(CA10<4.5,"ALTO",IF(CA10<=5,"SUPERIOR")))) -> BAJO | CC10: 1 | CD10: 3.8 | CE10: 3.7 | CF10: 3.7 | CG10: =((CD10*0.3)+(CE10*0.4)+(CF10*0.3)) -> 3.73 | CH10: =IF(CG10<3,"BAJO",IF(CG10<4,"BASICO",IF(CG10<4.5,"ALTO",IF(CG10<=5,"SUPERIOR")))) -> BASICO | CI10: 1 | CJ10: 4.2 | CK10: 4.2 | CL10: 4.2 | CM10: =((CJ10*0.3)+(CK10*0.4)+(CL10*0.3)) -> 4.2 | CN10: =IF(CM10<3,"BAJO",IF(CM10<4,"BASICO",IF(CM10<4.5,"ALTO",IF(CM10<=5,"SUPERIOR")))) -> ALTO | CO10: 1 | CP10: 5 | CQ10: 5 | CR10: 5 | CS10: =((CP10*0.3)+(CQ10*0.4)+(CR10*0.3)) -> 5 | CT10: =IF(CS10<3,"BAJO",IF(CS10<4,"BASICO",IF(CS10<4.5,"ALTO",IF(CS10<=5,"SUPERIOR")))) -> SUPERIOR | CU10: 2 | CY10: =((CV10*0.3)+(CW10*0.4)+(CX10*0.3)) -> 0 | CZ10: =IF(CY10<3,"BAJO",IF(CY10<4,"BASICO",IF(CY10<4.5,"ALTO",IF(CY10<=5,"SUPERIOR")))) -> BAJO | DA10: 2 | DB10: 3.5 | DC10: 4 | DD10: 3.5 | DE10: =((DB10*0.3)+(DC10*0.4)+(DD10*0.3)) -> 3.7 | DF10: =IF(DE10<2.95,"BAJO",IF(DE10<3.95,"BASICO",IF(DE10<4.45,"ALTO",IF(DE10<=5,"SUPERIOR")))) -> BASICO | DG10: 0 | DI10: =IF(DH10<3,"BAJO",IF(DH10<4,"BASICO",IF(DH10<4.5,"ALTO",IF(DH10<=5,"SUPERIOR")))) -> BAJO | DJ10: =AVERAGE(M10,Y10,AE10,AK10,AW10,BC10,BI10,BO10,CA10,DE10,DH10,CY10,CS10,CM10,CG10,AQ10,S10) -> 2.89375 | DK10: =$DK$2 -> Comprende el concepto de números reales, su relación de orden y las propiedades de sus operaciones, así como las relaciones de semejanza y congruencia de distintas figuras geométricas. | DL10: =DL9 -> Aplica correctamente las propiedades de las operaciones de números reales y expresiones algebraicas en la resolución de problemas. | DM10: =DM9 -> Valora el uso del pensamiento lógico a la hora de plantear y resolver problemas de las matemáticas y de la vida cotidiana. | DN10: =DN9 -> Reconoce y clasifica variables aleatorias, comprendiendo sus tipos y características; además, interpreta la información presentada en tablas de frecuencias y diagramas estadísticos, explicando su significado en contextos diversos. | DO10: =DO9 -> Organiza y analiza datos mediante la construcción de tablas de frecuencias y diagramas estadísticos, identificando variables aleatorias y utilizando estas representaciones para resolver situaciones problema. | DP10: =DP9 -> Muestra disposición y responsabilidad en el manejo y análisis de datos, participando activamente en actividades individuales y colaborativas, y comunicando información estadística con claridad y sentido crítico. | DQ10: =DQ9 -> Analiza las características de la literatura prehispánica y la literatura del descubrimiento y la conquista en Colombia identificando sus elementos fundamentales y su impacto en la cultura y el lenguaje actual. | DR10: =DR9 -> Realiza comprensión lectora cuando analiza un texto desde el discurso de la Enunciación e identifica la función de cada uno de sus componentes. Responde preguntas en los tres niveles de lectura a una leyenda del Caribe. | DS10: =DS9 -> Muestra disposición para participar activamente en las clases, promoviendo el respeto por las ideas ajenas y reconociendo la importancia de la precisión como una herramienta clave para una comunicación | ... FJ10: =FJ9 -> Identifica y reconoce sus pricipales deberes y derechos dentro y fuera de la Institución educativa.
